Workbook
Name AdminLock: OFFSET([1]Control!$D$4,0,0)
Name AnswerLkp: [2]QUESTLOOKUP!$A$2:$B$5
Name AR: OFFSET([1]Master!$X$2,0,0,COUNTA([1]Master!$X$1:$X$65536)-1,1)
Name Area: OFFSET([1]Master!$AE$1,0,0,COUNTA([1]Master!$AE$1:$AE$65536),1)
Name Asp: OFFSET([1]Master!$P$2,0,0,COUNTA([1]Master!$P$1:$P$65536)-1,1)
Name Attributes: OFFSET([1]Master!$A$2,0,0,COUNTA([1]Master!$A$1:$A$65536)-1,1)
Name BestPracticesCriteria: OFFSET([1]Master!$AK$2:$AL$3,0,0)
Name Blandine_Lepoutre: Resultats!$B$7
Name CalcMode1: OFFSET([1]Control!$B$4,0,0)
Name CalcMode2: OFFSET([1]Control!$B$5,0,0)
Name CalcMode3: OFFSET([1]Control!$B$6,0,0)
Name Cat: OFFSET([1]Master!$H$2,0,0,COUNTA([1]Master!$H$1:$H$65536)-1,1)
Name Cat_1: [2]QUESTLOOKUP!$D$2:$E$6
Name Cat_2: [2]QUESTLOOKUP!$G$2:$H$6
Name Cat_3: [2]QUESTLOOKUP!$J$2:$K$6
Name Compute: OFFSET([1]Control!$B$8,0,0)
Name Date: #REF!
Name Date: #REF!
Name Date: #REF!
Name Date: #REF!
Name Filters: OFFSET([1]Control!$E$2,0,0,COUNTA([1]Control!$E$1:$E$65536)-1,1)
Name Full: Reponses!$D$2:$D$5
Name Generation: OFFSET([1]Control!$D$6,0,0)
Name Geomarket: OFFSET([1]Master!$AF$1,0,0,COUNTA([1]Master!$AF$1:$AF$65536),1)
Name MS: OFFSET([1]Master!$I$2,0,0,COUNTA([1]Master!$I$1:$I$65536)-1,1)
Name MSS: OFFSET([1]Master!$K$2,0,0,COUNTA([1]Master!$K$1:$K$65536)-1,1)
Name NonComplianceCriteria: OFFSET([1]Master!$AM$2:$AO$3,0,0)
Name NonComplianceTwoCriteria: OFFSET([1]Master!$AM$5:$AO$6,0,0)
Name ON: Reponses!$A$2:$A$3
Name ONP: Reponses!$C$2:$C$4
Name OuiNon: Reponses!$B$2:$B$4
Name Paper: OFFSET([1]Control!$B$10,0,0)
Name Papers: OFFSET([1]Control!$B$12,0,0,2,1)
Name QHSE: OFFSET([1]Master!$V$2,0,0,COUNTA([1]Master!$V$1:$V$65536)-1,1)
Name RecoList: OFFSET([1]Master!$AH$2,0,0,COUNTA([1]Master!$AH$1:$AH$65536)-1,1)
Name RecoListScore: OFFSET([1]Master!$AI$2,0,0,COUNTA([1]Master!$AH$1:$AH$65536)-1,2)
Name ScHigh: [1]Setup!#REF!
Name ScHigh: [1]Setup!#REF!
Name ScHigh: [1]Setup!#REF!
Name ScHigh: [1]Setup!#REF!
Name ScHigh: [1]Setup!#REF!
Name ScHigh: [1]Setup!#REF!
Name ScHigh: [1]Setup!#REF!
Name ScHigh: [1]Setup!#REF!
Name ScHigh: [1]Setup!#REF!
Name ScHigh: [1]Setup!#REF!
Name ScLow: [1]Setup!#REF!
Name ScLow: [1]Setup!#REF!
Name ScLow: [1]Setup!#REF!
Name ScLow: [1]Setup!#REF!
Name ScLow: [1]Setup!#REF!
Name ScLow: [1]Setup!#REF!
Name ScLow: [1]Setup!#REF!
Name ScLow: [1]Setup!#REF!
Name ScLow: [1]Setup!#REF!
Name ScLow: [1]Setup!#REF!
Name Scores: OFFSET([1]Control!$F$2,0,0,COUNTA([1]Control!$F$1:$F$65536)-1,1)
Name Segment: OFFSET([1]Master!$AG$1,0,0,COUNTA([1]Master!$AG$1:$AG$65536),1)
Name Site: #REF!
Name Site: #REF!

Sheet How to conduct the inspection
B1: How to conduct the inspection?
B2: Just quick reminder about the inspection process under your responsibility.
B4: As Leader of the inspection you have to:
B5: · Contact local area responsible and manager to verify their availability
B6: · Bring check-list during the inspection
B7: · Define the scope and area to inspected depending of the number of participant
B8: · We want a 1h inspection thus if you are a small group or the area is too big remove a topic or split the group
B9: · Ask if there is a hazard not reported in the check-list and if employee feel safe during their daily work
B10: · Always debrief after the inspection to clarify action item. Be pragmatic : do not create too many action items (max 15!) just focus on main risk.
B11: · Take picture when possible
B12: · Do not execute everything! Share your knowledge and experience with your members. Ask other LPT inspectors to fill the excel “.xls” form and RWP associated. Review it.
B13: · Create the QUEST report:
... B21: · Notify Management & HSE

Sheet Cover
A4: Title | B4: FCS-Abbeville HSE Inspection Template
A5: PN | B5: 102085485
A6: Revision | B6: AA
A7: Date | B7: 42499
A8: Owner | B8: V. Verdier (vverdier@slb.com)
A9: Author | B9: S. Patterson (SPatterson2@slb.com)
A12: Revision History | B12: First Revision | C12: 0.1 | D12: 39965
B13: Small updates to questions to include parking lots | C13: 0.2 | D13: 39995
B14: update done by HSE | C14: 0.3 | D14: 40102
B15: update done by HSE | C15: 0.4 | D15: 40507 | E15: Vverdier
B16: update done by HSE : add and remove questions | C16: 0.5 | D16: 40940 | E16: Vverdier
B17: update done by HSE : add and remove questions | C17: 0.6 | D17: 41062 | E17: Vverdier
B18: update done by HSE : add and remove questions | C18: 0.7 | D18: 41092 | E18: Vverdier
B19: update done by HSE : add question about fume hoods | C19: 0.8 | D19: 41249 | E19: Vverdier
B20: Revue du Calcul des "N/A" Possibilité de répondre N/A et Partiellement à toutes les questions Ajout de la colonne "X" dans la page "Résultats" | C20: 0.9 | D20: 41260 | E20: Vverdier
B21: Modify to meet FCS criteria | C21: 1 | D21: 41822 | E21: Vverdier | F21: Karim Dridi | G21: Stéphane Duchossois
B22: Last update and PN creation in GeMS | C22: AK | D22: 42499 | E22: Ajupin | F22: Karim Dridi

Sheet Reponses
A1: ON | B1: OuiNon | C1: ONP | D1: Full
A2: Oui | B2: Oui | C2: Oui | D2: Oui
A3: Non | B3: Non | C3: Partiellement | D3: Partiellement
B4: N/A | C4: Non | D4: Non
D5: N/A

Sheet Instructions
B3: Preparation | C3: Under the tab "Resultats", fill in the details regarding the inspection (HSE Zone, Line Manager, Site, Site person-in-charge, date of inspection and the names of the inspectors). Limit the "Site" name to 22 characters.
C4: Save the Inspection Sheet with a different name. Ex: "FCS_HSE_Inspection_MFG_RSP_Lab.xlsx".
C5: Print out a copy of all the inspection sheets for each member of the inspection team.
C6: Before the inspection, the inspection team should meet together to nominate a lead inspector, review the inspection sheet and agree on the details of how the inspection will be carried out.
B8: Conducting the inspection | C8: The inspection is divided into 8 sections: Safety (SAF), Personal Protective Equipment (PPE), Chemicals (CHM), Environment (ENV), Mechanical Lifting (ML), Injury Prevention (IP), Fire Prevention & Mitigation (FIRE) and Security (SEC)
C9: Try to conver all subject. You may split the inspection group to cover all subjects.
C10: Each section has its own worksheet with multiple questions to be answered during the inspection.
C11: The questions have been designed to be answered as much as possible through visual inspection only.
C12: The inspectors are encouraged to speak to personnel working in the inspected site to help them most accurately answer the questions.
C13: Each question has an associated "Response Type". Each "Response Type" has a possible range of answers.
C14: Ideally, all the questions should have "Oui" ("Yes") as the response.
C15: Answer a question with "Oui" ("Yes") when there is a high level of compliance.
C16: Answer a question with "Partiellement" ("Partially") when there is a moderate level of compliance, or when neither "Oui" ("Yes") nor "Non" ("No") is the best response.
C17: Answer a question with "Non" ("No") when there is a low level of compliance.
C18: Answer a question with "N/A" ("N/A") when the activity concerned by the question NEVER takes places in the site inspected (i.e. the activity has been completely eliminated).
C19: For any question answered "Non" or "Partiellement", fill in the comment box with the reason for the answer chosen. This will help with the creation of action items and a remedial work plan.
B21: Updating the Results | C21: Transfer the results to the Inspection Worksheet. For each question there is a pull down menu with the permitted responses.
C22: Select the response that corresponds to what was found during the inspection.
C23: The results are tabulated automatically on each section's sheet and on the "Resultats" worksheep.
C24: If a subject is non applicable (i.e. Mechanical Lifting) right clic on the concerned line in the "Resultats" sheet and "Hide" it will remove the section from the chart.
C25: The Radar Graph is updated automatically on the "Resultats" worksheet.
B27: Creating Action Items/Remedial Work Plan | C27: Based on the "Comments" from the inspection, create corrective actions to raise the level of compliance in the zone.
C28: In the tab "RWP" write a summary of the action item in the column "Action Item Summary" in less than 50 characters.
C29: In the column "Comments" describe in further detail the action to take in less than 255 characters.
C30: Assign a priority to the action item from the pull down menus (L, M or H)
C31: Assign a person responsible for the action. Enter the GIN number or LDAP alias of the responsible person. These can be found in Schlumberger's LDAP Directory accesible from The Hub. Attention: the LDAP alias is not always the same as a person's e-mail address.
C32: Enter a desired completion date for the action item in dd-MMM-yy format. Ex. 05-Aug-09. Normal completion dates are 2 weeks from today's date.
B34: Creating a Quest Report | C34: In Quest click on "Create New Entry" and "Create an Audit/Inspection Report".
C35: On the following page, click on "Create an Audit".
C36: Fill in the details on the page that follows. In the box "Category" select "Inspection - Facility".
C37: Click on "Save Details".
C38: Note the number of the Quest report and enter this number in the "Resultats" worksheet.
C39: The report name must be : SRXX_(LPT)_HSE Inspection - "Zone" - YYYYMMDD - "Score%". Ex: "FCS_HSE_Inspection_"MFG_Integration_Lab"_20121103_"85%".xls"
B41: Importing Action Items/Remedial Work Plan | C41: Save the Inspection Worksheet as a *.xlsx file. Save a copy as a *.xls file.
C42: Under the tab "Action Items" in the Quest report, click on "Import Action(s)".
C43: Click on "Browse" and open the *.xls copy of the Inspection Worksheet. Click on "Import Data". The action items from the Inspection worksheet have been automatically loaded into the Quest report.
C44: You can edit the action items manually in the Quest report, if needed.
B46: Archiving the Inspection Sheet. | C46: From the Quest Report main screen, select the tab "Attachments".
C47: Click on "Add Attachments".
C48: Click on "Browse" and open the *.xlsx copy of the Inspection Worksheet.
...

Sheet Resultats
B1: FCS HSE Inspection Sheet
B2: CENTRE / CENTER
B3: FCS
B4: Zone Inspectée/Inspected Site
B5: Zone SET MFG
B6: Responsable de centre / Line Manager
B7: Thibault Julien
B8: Responsable de zone /Site Person-in-Charge
B9: Omar GHECHI
B10: Date(s) d'Inspection/Inspection Date(s)
B11: 45967
B12: Inspecteur(s)/Inspector(s)
B13: SET Member 1 Cissey Bello
B14: SET Member 2 Moncef Mimi
B15: Manager : Karim Benrabah
B16: Team Members : Omar Ghechi
B17: Mickael Courbo
B18: Laurent BREGERE
B19: Numéro Rapport Quest/Quest Report Number
B20: 20251113083710
B21: Résultats/Results | E21: "X"
B22: =FIRE!C2 -> Prévention Incendie / Fire Prevention & Mitigation | C22: FIRE | D22: =FIRE!F2 -> 0.85365854 | E22: x | F22: =FIRE!J22 -> 8.2
B23: =SAF!C2 -> Sécurite / Safety | C23: SAF | D23: =SAF!F2 -> 1 | E23: x | F23: =SAF!J14 -> 3.4
B24: =PPE!C2 -> Equipement de Protection Individuel (EPI)/Personal Protective Equipement (PPE) | C24: PPE | D24: =PPE!F2 -> 0.92307692 | E24: x | F24: =PPE!J22 -> 3.9
B25: =CHM!C2 -> Produits Chimiques / Chemicals | C25: CHM | D25: =CHM!F2 -> 0.84615385 | E25: x | F25: =CHM!J18 -> 3.9
B26: =ENV!C2 -> Environnement / Environment | C26: ENV | D26: =ENV!F2 -> 1 | E26: x | F26: =ENV!J17 -> 2.3
B27: =IP!C2 -> Prevention des Blessures/Injury Prevention | C27: IP | D27: =IP!F2 -> 0.91463415 | E27: x | F27: =IP!J23 -> 3.8
B28: =ML!C2 -> Levage Mécanique / Mechanical Lifting | C28: ML | D28: =ML!F2 -> 0.953125 | E28: x | F28: =ML!J16 -> 3.2
B29: =SEC!C2 -> Sureté / Security | C29: SEC | D29: =SEC!F2 -> 1 | E29: x | F29: =SEC!J17 -> 3.1
B30: Moyenne/Average | D30: {=IFERROR(SUM(IF(D22:D29="",0,D22:D29)*F22:F29*(E22:E29="x"))/SUM(F22:F29*(E22:E29="x")),"")} -> 0.91904433 | F30: =SUM(F22:F29) -> 31.8

Sheet FIRE
C2: Prévention Incendie / Fire Prevention & Mitigation | F2: =IFERROR(M24,"") -> 0.85365854 | N2: Zone Inspectée/Inspected Site | O2: =Resultats!B5 -> Zone SET MFG
N3: Date(s) d'Inspection/Inspection Date(s) | O3: =Resultats!B11 -> 45967
B5: Q-Nr | C5: Question (FR) | D5: Question (EN) | E5: Categorie | F5: Reponse | G5: Resultat | H5: Resultat Pondere | I5: Resultat Max | J5: Resultat Max Pondere | N5: Commentaires/Comments | P5: Assessor Guidance | R5: P
B6: 1 | C6: Y-a-t-il présence d'extincteurs appropriés au risque dans la zone (1 extincteur pour 200m2 / 1 type par risque) ? | D6: Is there fire extinguishers suited to the risk in the area (1 fire extinguisher for 200m2 / 1 type by risk) ? | E6: 1 | F6: Oui | G6: =IF(F6="Oui",1,IF(F6="Partiellement",0.5,0)) -> 1 | H6: =G6*IF(E6=1, 0.7, 0.3) -> 0.7 | I6: =IF(F6="N/A", 0,1) -> 1 | J6: =I6*IF(E6=1, 0.7, 0.3) -> 0.7 | R6: Tickets Services techniques
B7: 2 | C7: Les extincteurs ont été inspectés et la date n'est pas dépassée (validité 1 an, indiqué sur étiquette de contrôle)? | D7: Fire extinguishershave been inspected and control date is still valid (validity 1 year, printed on control label) ? | E7: 1 | F7: Non | G7: =IF(F7="Oui",1,IF(F7="Partiellement",0.5,0)) -> 0 | H7: =G7*IF(E7=1, 0.7, 0.3) -> 0 | I7: =IF(F7="N/A", 0,1) -> 1 | J7: =I7*IF(E7=1, 0.7, 0.3) -> 0.7 | N7: Non-conformité pris en charge | R7: Tickets Services techniques
B8: 3 | C8: Les extincteurs sont avec leur support en bonne etat (cone pyramide ou fixé au mur), identifiés, signalés et en cohérence avec le numéro de l'extincteur (plaque d'identification à proximité) ? | D8: Fire extinguishers are with their support (fix to the wall or pyramidal support), identified and signaled (identification plate near the extinguisher) ? | E8: 2 | F8: Oui | G8: =IF(F8="Oui",1,IF(F8="Partiellement",0.5,0)) -> 1 | H8: =G8*IF(E8=1, 0.7, 0.3) -> 0.3 | I8: =IF(F8="N/A", 0,1) -> 1 | J8: =I8*IF(E8=1, 0.7, 0.3) -> 0.3 | R8: Tickets Services techniques
B9: 4 | C9: En cas de présence d'extincteurs ou de Robinet d'Incendie Armé (RIA), sont-ils dégagés et facilement accessibles ? | D9: In case of presence of Fire Hose Reel, they are brought out and do easily accessible ? | E9: 1 | F9: Oui | G9: =IF(F9="Oui",1,IF(F9="Partiellement",0.5,0)) -> 1 | H9: =G9*IF(E9=1, 0.7, 0.3) -> 0.7 | I9: =IF(F9="N/A", 0,1) -> 1 | J9: =I9*IF(E9=1, 0.7, 0.3) -> 0.7 | P9: RIA = un tuyau semi-rigide, enroulé sur un dévidoir qui est parfois pivotant | R9: 5S par responsable de zone.
B10: 5 | C10: Les issues de secours sont-elles dégagées et libre d'accès ? | D10: Are the Emergency Exits free and accessible ? | E10: 1 | F10: Oui | G10: =IF(F10="Oui",1,IF(F10="Partiellement",0.5,0)) -> 1 | H10: =G10*IF(E10=1, 0.7, 0.3) -> 0.7 | I10: =IF(F10="N/A", 0,1) -> 1 | J10: =I10*IF(E10=1, 0.7, 0.3) -> 0.7 | R10: 5S par responsable de zone.
B11: 6 | C11: Les issues de secours sont-elles signalées (bloc secours lumineux vert) et les lampes témoins sont elles allumées ? | D11: Are the Emergency Exits indicated and warning lights of the switched on ? | E11: 2 | F11: Oui | G11: =IF(F11="Oui",1,IF(F11="Partiellement",0.5,0)) -> 1 | H11: =G11*IF(E11=1, 0.7, 0.3) -> 0.3 | I11: =IF(F11="N/A", 0,1) -> 1 | J11: =I11*IF(E11=1, 0.7, 0.3) -> 0.3 | R11: Tickets Services techniques
B12: 7 | C12: Le cas échant, les portes sont libres de tout obstacle à leur fermeture ? | D12: Where appropriate, fire doors are free of any obstacle to their closure? | E12: 1 | F12: Oui | G12: =IF(F12="Oui",1,IF(F12="Partiellement",0.5,0)) -> 1 | H12: =G12*IF(E12=1, 0.7, 0.3) -> 0.7 | I12: =IF(F12="N/A", 0,1) -> 1 | J12: =I12*IF(E12=1, 0.7, 0.3) -> 0.7 | R12: 5S par responsable de zone.
B13: 8 | C13: Est-il possible d'ouvrir la porte de sortie de secours par un geste simple? | D13: It is possible to easily open the safety exit door ? | E13: 1 | F13: Oui | G13: =IF(F13="Oui",1,IF(F13="Partiellement",0.5,0)) -> 1 | H13: =G13*IF(E13=1, 0.7, 0.3) -> 0.7 | I13: =IF(F13="N/A", 0,1) -> 1 | J13: =I13*IF(E13=1, 0.7, 0.3) -> 0.7 | R13: Tickets Services techniques
B14: 9 | C14: Les couloirs sont-ils dégagés sur toute leur longueur et libre d'accès ? | D14: Are the corridors free along their way and accessible ? | E14: 2 | F14: Partiellement | G14: =IF(F14="Oui",1,IF(F14="Partiellement",0.5,0)) -> 0.5 | H14: =G14*IF(E14=1, 0.7, 0.3) -> 0.15 | I14: =IF(F14="N/A", 0,1) -> 1 | J14: =I14*IF(E14=1, 0.7, 0.3) -> 0.3 | N14: Palette sur chemin (à deplacer) | R14: 5S par responsable de zone.
B15: 10 | C15: Les plans d'évacuations sont ils affichés et à jour ? | D15: Are evacuation map displayed and up to date ? | E15: 1 | F15: Oui | G15: =IF(F15="Oui",1,IF(F15="Partiellement",0.5,0)) -> 1 | H15: =G15*IF(E15=1, 0.7, 0.3) -> 0.7 | I15: =IF(F15="N/A", 0,1) -> 1 | J15: =I15*IF(E15=1, 0.7, 0.3) -> 0.7 | R15: Responsable HSE (Marc Oszwald)
B16: 11 | C16: Il n'y a pas de surcharge sur les prises électriques : 1 multiprise à 6 prises max. pas de machine à café, bouilloires, ni convecteurs électriques ? | D16: There is no overload on sockets: 1 multiple socket with 6 socket max, no coffee machine, kettles, nor electric heating equipment ? | E16: 1 | F16: Oui | G16: =IF(F16="Oui",1,IF(F16="Partiellement",0.5,0)) -> 1 | H16: =G16*IF(E16=1, 0.7, 0.3) -> 0.7 | I16: =IF(F16="N/A", 0,1) -> 1 | J16: =I16*IF(E16=1, 0.7, 0.3) -> 0.7 | P16: Pour éviter toute confusion (ampérage, etc…) les multiprises ne sont pas recommandées. Il préférable de contacter les SG pour qu'il adapte la ligne électrique. | R16: Tickets Services techniques
B17: 12 | C17: Présence de La goupille et plombage sur l'extincteur ? | E17: 1 | F17: Oui | G17: =IF(F17="Oui",1,IF(F17="Partiellement",0.5,0)) -> 1 | H17: =G17*IF(E17=1, 0.7, 0.3) -> 0.7 | I17: =IF(F17="N/A", 0,1) -> 1 | J17: =I17*IF(E17=1, 0.7, 0.3) -> 0.7
B18: 13 | C18: Le salarié connait-il ces pilotes d'évacuation dans sa zone ( guide file, serre file ) | E18: 1 | F18: Partiellement | G18: =IF(F18="Oui",1,IF(F18="Partiellement",0.5,0)) -> 0.5 | H18: =G18*IF(E18=1, 0.7, 0.3) -> 0.35 | I18: =IF(F18="N/A", 0,1) -> 1 | J18: =I18*IF(E18=1, 0.7, 0.3) -> 0.7 | N18: Afficher le plan d'vacuation et les serre et guide file | R18: Responsable HSE (Marc Oszwald)
B19: 14 | C19: Les portes et fenêtres des bureaux inoccupés sont fermées afin de limiter la propagation des flammes ? | D19: The doors and windows of inoccupied offices are closed to limit the fire propagation ? | E19: 2 | F19: Oui | G19: =IF(F19="Oui",1,IF(F19="Partiellement",0.5,0)) -> 1 | H19: =G19*IF(E19=1, 0.7, 0.3) -> 0.3 | I19: =IF(F19="N/A", 0,1) -> 1 | J19: =I19*IF(E19=1, 0.7, 0.3) -> 0.3 | R19: Rappel de la règle / communication
H21: =SUM(H6:H19) -> 7
J22: =SUM(J6:J19) -> 8.2
K24: Pourcentage | M24: {=SUM(H6:H19)/SUM(J6:J19*(F6:F19<>"N/A")*(F6:F19<>""))} -> 0.85365854

Sheet SAF
C2: Sécurite / Safety | F2: =IFERROR(M16,"") -> 1 | N2: Zone Inspectée/Inspected Site | O2: =Resultats!B5 -> Zone SET MFG
N3: Date(s) d'Inspection/Inspection Date(s) | O3: =Resultats!B11 -> 45967
B5: Q-Nr | C5: Question (FR) | D5: Question (EN) | E5: Categorie | F5: Reponse | G5: Resultat | H5: Resultat Pondere | I5: Resultat Max | J5: Resultat Max Pondere | N5: Commentaires/Comments | P5: Assessor Guidance | R5: QUEST Action Item
B6: 13 | C6: L'outillage électrique, les câbles, etc. sont en bon état, dépourvus de dommage ? La batterie de defibrillateurs est bien chargée? | D6: Are the electric tools, cables, etc. in good condition and free of damage? | E6: 1 | F6: Oui | G6: =IF(F6="Oui",1,IF(F6="Partiellement",0.5,0)) -> 1 | H6: =G6*IF(E6=1, 0.7, 0.3) -> 0.7 | I6: =IF(F6="N/A", 0,1) -> 1 | J6: =I6*IF(E6=1, 0.7, 0.3) -> 0.7 | N6: Pas de defibrillateur dans la Zone | R6: Responsable de zone (Support Laurent Jolly) entretien des équipements électriques
B7: 14 | C7: Toutes les prises électriques sont en bon état ? | D7: Are the electrical plugs in good condition? | E7: 1 | F7: Oui | G7: =IF(F7="Oui",1,IF(F7="Partiellement",0.5,0)) -> 1 | H7: =G7*IF(E7=1, 0.7, 0.3) -> 0.7 | I7: =IF(F7="N/A", 0,1) -> 1 | J7: =I7*IF(E7=1, 0.7, 0.3) -> 0.7 | N7: Supprimer la multiprise | R7: Tickets Services techniques
B8: 15 | C8: Le risque électrique est-il correctement adressé dans la zone? Incluant les nouveaux équipements et les mises à la terre des équipements concernés? | D8: Is the site free from any non-identified electrical risk? Including new and concerned equipments (benches, earth grounding of chemical cabinets…) | E8: 1 | F8: Oui | G8: =IF(F8="Oui",1,IF(F8="Partiellement",0.5,0)) -> 1 | H8: =G8*IF(E8=1, 0.7, 0.3) -> 0.7 | I8: =IF(F8="N/A", 0,1) -> 1 | J8: =I8*IF(E8=1, 0.7, 0.3) -> 0.7 | R8: Responsable de zone (Support Laurent Jolly) entretien des équipements électriques
B9: 16 | C9: Les disjoncteurs et interrupteurs électriques sont visibles et accessibles (pas d'encombrement empêchant l'accès)? | D9: Are the electrical circuit breakers visible and accessible? | E9: 1 | F9: Oui | G9: =IF(F9="Oui",1,IF(F9="Partiellement",0.5,0)) -> 1 | H9: =G9*IF(E9=1, 0.7, 0.3) -> 0.7 | I9: =IF(F9="N/A", 0,1) -> 1 | J9: =I9*IF(E9=1, 0.7, 0.3) -> 0.7 | P9: rechercher le coup de poing d'arrêt d'urgence | R9: Responsable de zone (Support Laurent Jolly)
B10: 17 | C10: Les portes, les fenêtres, les escaliers, les revêtements de sol sont dans un état acceptable ? | D10: Are the doors, windows, stairs and floor coverings in an acceptable condition? | E10: 2 | F10: Oui | G10: =IF(F10="Oui",1,IF(F10="Partiellement",0.5,0)) -> 1 | H10: =G10*IF(E10=1, 0.7, 0.3) -> 0.3 | I10: =IF(F10="N/A", 0,1) -> 1 | J10: =I10*IF(E10=1, 0.7, 0.3) -> 0.3 | R10: Responsable de zone (Support Laurent Jolly)
B11: 18 | C11: La signalétique de sécurité est en place, claire et visible dans la zone? | D11: Is the safety signage in place, understandable and visible in the area? | E11: 2 | F11: Oui | G11: =IF(F11="Oui",1,IF(F11="Partiellement",0.5,0)) -> 1 | H11: =G11*IF(E11=1, 0.7, 0.3) -> 0.3 | I11: =IF(F11="N/A", 0,1) -> 1 | J11: =I11*IF(E11=1, 0.7, 0.3) -> 0.3 | R11: Responsable de zone (Support M.Oszwald)
H13: =SUM(H6:H11) -> 3.4
J14: =SUM(J6:J11) -> 3.4
K16: Pourcentage | M16: {=SUM(H6:H11)/SUM(J6:J11*(F6:F11<>"N/A")*(F6:F11<>""))} -> 1

Sheet PPE
C2: Equipement de Protection Individuel (EPI)/Personal Protective Equipement (PPE) | F2: =IFERROR(M24,"") -> 0.92307692 | N2: Zone Inspectée/Inspected Site | O2: =Resultats!B5 -> Zone SET MFG
N3: Date(s) d'Inspection/Inspection Date(s) | O3: =Resultats!B11 -> 45967
B5: Q-Nr | C5: Question (FR) | D5: Question (EN) | E5: Categorie | F5: Reponse | G5: Resultat | H5: Resultat Pondere | I5: Resultat Max | J5: Resultat Max Pondere | N5: Commentaires/Comments | P5: Assessor Guidance | R5: QUEST Action Item
B6: 19 | C6: Tous les salariés, les intérimaires et les sous-traitants respectent le port des EPI dans les zones concernées ? | D6: Do all employees and contractors wear PPE as requested in the inspected area? | E6: 1 | F6: Oui | G6: =IF(F6="Oui",1,IF(F6="Partiellement",0.5,0)) -> 1 | H6: =G6*IF(E6=1, 0.7, 0.3) -> 0.7 | I6: =IF(F6="N/A", 0,1) -> 1 | J6: =I6*IF(E6=1, 0.7, 0.3) -> 0.7 | R6: Rappel de la règle
B7: 20 | C7: Le management montre-il l'exemple, en portant les EPI nécessaires dans les zones concernées? | D7: Does all line management lead by example, wearing PPE at all times as per the local PPE plan? | E7: 1 | F7: Oui | G7: =IF(F7="Oui",1,IF(F7="Partiellement",0.5,0)) -> 1 | H7: =G7*IF(E7=1, 0.7, 0.3) -> 0.7 | I7: =IF(F7="N/A", 0,1) -> 1 | J7: =I7*IF(E7=1, 0.7, 0.3) -> 0.7 | R7: Rappel de la règle
B8: 21 | C8: Les zones de travail où des EPI sont imposés sont-elles clairement identifiées et communiquées à toute personne entrant dans la zone? | D8: Are all designated work areas requiring PPE clearly marked and communicated to all that enter the area? | E8: 1 | F8: Oui | G8: =IF(F8="Oui",1,IF(F8="Partiellement",0.5,0)) -> 1 | H8: =G8*IF(E8=1, 0.7, 0.3) -> 0.7 | I8: =IF(F8="N/A", 0,1) -> 1 | J8: =I8*IF(E8=1, 0.7, 0.3) -> 0.7 | P8: Rechercher la présence des lignes jaunes au sol et du panneau jaune EPI indiquant les EPIs à porter dans la zone | R8: Tickets Services techniques
B9: 22 | C9: Des gants appropriés sont-ils portés quand il existe un risque de blessure aux mains (pincement, coupure)? | D9: Are appropriate gloves being worn where there is a risk of abrasion, pinch point or cuts to the hand? | E9: 2 | F9: Oui | G9: =IF(F9="Oui",1,IF(F9="Partiellement",0.5,0)) -> 1 | H9: =G9*IF(E9=1, 0.7, 0.3) -> 0.3 | I9: =IF(F9="N/A", 0,1) -> 1 | J9: =I9*IF(E9=1, 0.7, 0.3) -> 0.3 | R9: Responsable de zone (Support : PPE coordinator : Alexandra Lemay).
B10: 23 | C10: Les gants résistants aux produits chimiques sont-ils disponibles et portés pendant la manipulation des produits chimiques conformement aux FDS? | D10: Are chemical resistant gloves available and worn when handling chemicals as per the MSDS? | E10: 2 | F10: Non | G10: =IF(F10="Oui",1,IF(F10="Partiellement",0.5,0)) -> 0 | H10: =G10*IF(E10=1, 0.7, 0.3) -> 0 | I10: =IF(F10="N/A", 0,1) -> 1 | J10: =I10*IF(E10=1, 0.7, 0.3) -> 0.3 | R10: Rappel de la règle
B11: 24 | C11: Des gants résistants aux températures chaudes / froides sont-ils à disposition et portés pendant la manipulation d'équipement ou matériel chaud / froid ? | D11: Are high / low temperature gloves available and worn when handling hot / cold equipment or materiel ? | E11: 2 | F11: N/A | G11: =IF(F11="Oui",1,IF(F11="Partiellement",0.5,0)) -> 0 | H11: =G11*IF(E11=1, 0.7, 0.3) -> 0 | I11: =IF(F11="N/A", 0,1) -> 0 | J11: =I11*IF(E11=1, 0.7, 0.3) -> 0 | P11: Attention le type de gant varie en fonction de l'activité : chaud, froid, azote liquide,… | R11: Responsable de zone (Support : PPE coordinator : Alexandra Lemay)
B12: 25 | C12: Les vetements de travail bleus Schlumberger sont elles portées dans les zones identifiées? | D12: Are Schlumberger protection clothing Blue worn by all personnel in all requested areas? | E12: 2 | F12: Oui | G12: =IF(F12="Oui",1,IF(F12="Partiellement",0.5,0)) -> 1 | H12: =G12*IF(E12=1, 0.7, 0.3) -> 0.3 | I12: =IF(F12="N/A", 0,1) -> 1 | J12: =I12*IF(E12=1, 0.7, 0.3) -> 0.3 | P12: Attention : certains sous-traitants sont autorisés à porter les tenues de leurs employeurs | R12: Rappel de la règle
B13: 26 | C13: Les casques blancs sont ils portés par les employés (à moins qu'ils ne soient nouveaux ou visiteurs dans ce cas ils doivent porter des casques de couleur jaune)? | D13: Are white hard hats used by all employees, unless they are short term employees or visitors in which case yellow colored hard hats should be used? | E13: 2 | F13: Oui | G13: =IF(F13="Oui",1,IF(F13="Partiellement",0.5,0)) -> 1 | H13: =G13*IF(E13=1, 0.7, 0.3) -> 0.3 | I13: =IF(F13="N/A", 0,1) -> 1 | J13: =I13*IF(E13=1, 0.7, 0.3) -> 0.3 | R13: Responsable de zone (Support : PPE coordinator : Alexandra Lemay)
B14: 27 | C14: Les casques sont-ils inspectés annuellement? (Vérifier la présence de sticker de suivi) | D14: Are hard hats checked once a year? (Check sticker for follow up) | E14: 2 | F14: Oui | G14: =IF(F14="Oui",1,IF(F14="Partiellement",0.5,0)) -> 1 | H14: =G14*IF(E14=1, 0.7, 0.3) -> 0.3 | I14: =IF(F14="N/A", 0,1) -> 1 | J14: =I14*IF(E14=1, 0.7, 0.3) -> 0.3 | P14: Vérifier présence sticker dans le casque. Répondre "Yes" si 80% des casques inspectés, et "No" si < 50%. Inspection: 1. Etat général du casque : choc, endommagement ? 2. Etat de propreté du casque : Sale ? 3. Date de « péremption » : 3 ans en condition extrême (outside + permanent), 5 ans en utilisation « normale », 10 ans à partir de la date de fabrication. | R14: Responsable de la zone. Control des casques visiteurs (sticker). Casque personnel de la responsabilité de l'usager
B15: 28 | C15: Lors de la manipulation de produits chimiques dangereux pour les yeux, les lunettes-masques (goggle) à ventilation indirecte ou visière intègrale sont-elles disponibles et portées? | D15: When handling hazardous chemicals, are indirect-vented chemical goggles or face shield available and being worn? | E15: 2 | F15: N/A | G15: =IF(F15="Oui",1,IF(F15="Partiellement",0.5,0)) -> 0 | H15: =G15*IF(E15=1, 0.7, 0.3) -> 0 | I15: =IF(F15="N/A", 0,1) -> 0 | J15: =I15*IF(E15=1, 0.7, 0.3) -> 0 | R15: Responsable de zone (Support : PPE coordinator : Alexandra Lemay). Fournir boite EPI avec goggle
B16: 29 | C16: Les protections auditives sont elles portées dans les zones requises ? Ces zones sont elles clairement identifiées à l'entrée de la zone? | D16: Is hearing protection being worn in all noise hazard areas and have all these areas been clearly marked and indicated to those that enter the area? | E16: 2 | F16: Oui | G16: =IF(F16="Oui",1,IF(F16="Partiellement",0.5,0)) -> 1 | H16: =G16*IF(E16=1, 0.7, 0.3) -> 0.3 | I16: =IF(F16="N/A", 0,1) -> 1 | J16: =I16*IF(E16=1, 0.7, 0.3) -> 0.3 | P16: Zones requises : zones dans lesquelles l'exposition est équivalente ou supérieure à 80 dBA moyenne pondérée sur huit heures) Noise hazard areas : where exposure is equal to or more than an eight hour time weighted average of 80 dBA | R16: Responsable de zone (Support : Alexandra Lemay).
B17: 30 | C17: Lors de la manipulation de meule, une visière intégrale est elle disponible et portée? | D17: When using abrasive and grinding machines, is face shield available and being worn? | E17: 2 | F17: N/A | G17: =IF(F17="Oui",1,IF(F17="Partiellement",0.5,0)) -> 0 | H17: =G17*IF(E17=1, 0.7, 0.3) -> 0 | I17: =IF(F17="N/A", 0,1) -> 0 | J17: =I17*IF(E17=1, 0.7, 0.3) -> 0 | R17: Responsable de zone (Support : PPE coordinator : Alexandra Lemay). Fournir boite EPI avec visière
B18: 31 | C18: Lors d'activité en hauteur (au dessus de 1,8m), un harnais individuel est il disponible et porté? | D18: When working at heights, are body harness available and being worn? | E18: 2 | F18: N/A | G18: =IF(F18="Oui",1,IF(F18="Partiellement",0.5,0)) -> 0 | H18: =G18*IF(E18=1, 0.7, 0.3) -> 0 | I18: =IF(F18="N/A", 0,1) -> 0 | J18: =I18*IF(E18=1, 0.7, 0.3) -> 0 | R18: Responsable de zone (Support : PPE coordinator : Alexandra Lemay)
B19: 32 | C19: Les EPI sont ils correctement rangés dans boites dédiées à cet effet, facilement identifiable et correctement fixée? | D19: Are PPE properly stored in a dedicated PPE box? Are the PPE box properly fixed? | E19: 2 | F19: N/A | G19: =IF(F19="Oui",1,IF(F19="Partiellement",0.5,0)) -> 0 | H19: =G19*IF(E19=1, 0.7, 0.3) -> 0 | I19: =IF(F19="N/A", 0,1) -> 0 | J19: =I19*IF(E19=1, 0.7, 0.3) -> 0 | R19: Responsable de zone (Support : PPE coordinator : Alexandra Lemay). Commande boite de rangement EPI
H21: =SUM(H6:H18) -> 3.6
J22: =SUM(J6:J19) -> 3.9
K24: Pourcentage | M24: {=SUM(H6:H19)/SUM(J6:J19*(F6:F19<>"N/A")*(F6:F19<>""))} -> 0.92307692

Sheet CHM
C2: Produits Chimiques / Chemicals | F2: =IFERROR(M20,"") -> 0.84615385 | N2: Zone Inspectée/Inspected Site | O2: =Resultats!B5 -> Zone SET MFG
N3: Date(s) d'Inspection/Inspection Date(s) | O3: =Resultats!B11 -> 45967
B5: Q-Nr | C5: Question (FR) | D5: Question (EN) | E5: Categorie | F5: Reponse | G5: Resultat | H5: Resultat Pondere | I5: Resultat Max | J5: Resultat Max Pondere | N5: Commentaires/Comments | P5: Assessor Guidance | R5: QUEST Action Item
B6: 33 | C6: La zone est-elle dépourvue de produits chimiques renversés ? | D6: Are the workbenches free of chemical product spills? | E6: 1 | F6: Oui | G6: =IF(F6="Oui",1,IF(F6="Partiellement",0.5,0)) -> 1 | H6: =G6*IF(E6=1, 0.7, 0.3) -> 0.7 | I6: =IF(F6="N/A", 0,1) -> 1 | J6: =I6*IF(E6=1, 0.7, 0.3) -> 0.7 | R6: Rappel de la règle
B7: 34 | C7: Les produits chimiques sont-ils stockés dans une armoire appropriée et correctement ventilée? | D7: Are the chemicals stored in an approved and properly ventilated cabinet? | E7: 2 | F7: Oui | G7: =IF(F7="Oui",1,IF(F7="Partiellement",0.5,0)) -> 1 | H7: =G7*IF(E7=1, 0.7, 0.3) -> 0.3 | I7: =IF(F7="N/A", 0,1) -> 1 | J7: =I7*IF(E7=1, 0.7, 0.3) -> 0.3 | P7: Les armoires pour produit inflammable doivent être sous extraction et reliées à la terre. | R7: Rappel de la règle. Sinon commande armoire via HSE pour reference
B8: 35 | C8: Le nom du responsable "expert- Chimie" de la zone ainsi que son numéro de téléphone sont il affichés sur l'armoire chimique? | D8: Are the name of the "Chemical -expert" and his phone number on the chemical cabinet ? | E8: 2 | F8: Non | G8: =IF(F8="Oui",1,IF(F8="Partiellement",0.5,0)) -> 0 | H8: =G8*IF(E8=1, 0.7, 0.3) -> 0 | I8: =IF(F8="N/A", 0,1) -> 1 | J8: =I8*IF(E8=1, 0.7, 0.3) -> 0.3 | R8: Responsable de zone (Support : Pierre-Yves Corre)
B9: 36 | C9: Les douches de sécurité, les lave-oeil fixes ou portables, validés par HSE, sont disponibles, aisément visibles, accessibles et propres? | D9: Are HSE approved eye wash stations or bottles available and safety shower, clearly visible and accesible? | E9: 2 | F9: Oui | G9: =IF(F9="Oui",1,IF(F9="Partiellement",0.5,0)) -> 1 | H9: =G9*IF(E9=1, 0.7, 0.3) -> 0.3 | I9: =IF(F9="N/A", 0,1) -> 1 | J9: =I9*IF(E9=1, 0.7, 0.3) -> 0.3 | R9: Responsable de zone (Support : Alexandra Lemay)
B10: 37 | C10: Les douches de sécurité, les stations lave-œil sont-elles inspectées et les lave-œil bouteilles sont ils non périmées? | D10: Are eye wash bottles non-expired and eye wash station inspected ? | E10: 2 | F10: N/A | G10: =IF(F10="Oui",1,IF(F10="Partiellement",0.5,0)) -> 0 | H10: =G10*IF(E10=1, 0.7, 0.3) -> 0 | I10: =IF(F10="N/A", 0,1) -> 0 | J10: =I10*IF(E10=1, 0.7, 0.3) -> 0 | N10: Pas de douche ou lave œil à proximité | R10: Responsable de zone (Support : HSE)
B11: 38 | C11: Tous les bidons/containers sont-ils correctement stockés, fermés ? | D11: Are all the cans/containers correctly stored, closed? | E11: 2 | F11: Oui | G11: =IF(F11="Oui",1,IF(F11="Partiellement",0.5,0)) -> 1 | H11: =G11*IF(E11=1, 0.7, 0.3) -> 0.3 | I11: =IF(F11="N/A", 0,1) -> 1 | J11: =I11*IF(E11=1, 0.7, 0.3) -> 0.3 | R11: Responsable de zone (Support : Marc Oszwald)
B12: 39 | C12: Tous les produits chimiques sont-ils correctement séparés (base/acide, inflammables/comburants,toxique a part) et rangés avec soin ? | D12: Are the chemicals correctly separated (base/acid, flammables/oxidizers, toxic separated) and placed with care? | E12: 1 | F12: Oui | G12: =IF(F12="Oui",1,IF(F12="Partiellement",0.5,0)) -> 1 | H12: =G12*IF(E12=1, 0.7, 0.3) -> 0.7 | I12: =IF(F12="N/A", 0,1) -> 1 | J12: =I12*IF(E12=1, 0.7, 0.3) -> 0.7 | R12: Responsable de zone (Support : Alexandra Lemay) Afficher le poster des compatibilités.
B13: 40 | C13: Un inventaire récent (< 6 mois) avec date de péremption est il affiché sur l'armoire? | D13: Is a recent inventory (<3 month) posted on the cabinet? | E13: 2 | F13: Non | G13: =IF(F13="Oui",1,IF(F13="Partiellement",0.5,0)) -> 0 | H13: =G13*IF(E13=1, 0.7, 0.3) -> 0 | I13: =IF(F13="N/A", 0,1) -> 1 | J13: =I13*IF(E13=1, 0.7, 0.3) -> 0.3 | R13: Responsable de zone (Support : Marc Oszwald)
B14: 41 | C14: Les bidons/futs stockés portent-ils tous un étiquetage (nom du produit et pictogrammes de danger associés)? | D14: The containers stocked in the cabinet have label (product name and associated danger symbol)? | E14: 2 | F14: Oui | G14: =IF(F14="Oui",1,IF(F14="Partiellement",0.5,0)) -> 1 | H14: =G14*IF(E14=1, 0.7, 0.3) -> 0.3 | I14: =IF(F14="N/A", 0,1) -> 1 | J14: =I14*IF(E14=1, 0.7, 0.3) -> 0.3 | R14: Responsable de zone (Support : Marc Oszwald)
B15: 42 | C15: Est-ce que les fiches de données de sécurité (FDS) des produits chimiques utilisés sont disponibles ? | D15: Are the Material Safety Data Sheets (MSDS) of chemical products used available? | E15: 1 | F15: Oui | G15: =IF(F15="Oui",1,IF(F15="Partiellement",0.5,0)) -> 1 | H15: =G15*IF(E15=1, 0.7, 0.3) -> 0.7 | I15: =IF(F15="N/A", 0,1) -> 1 | J15: =I15*IF(E15=1, 0.7, 0.3) -> 0.7 | P15: Choisir au hasard 2 références dans l'armoire et vérifier si présents sur l'inventaire | R15: Responsable de zone (Support : Marc Oszwald)
H17: =SUM(H6:H15) -> 3.3
J18: =SUM(J6:J15) -> 3.9
K20: Pourcentage | M20: {=SUM(H6:H15)/SUM(J6:J15*(F6:F15<>"N/A")*(F6:F15<>""))} -> 0.84615385

Sheet ENV
C2: Environnement / Environment | F2: =IFERROR(M19,"") -> 1 | N2: Zone Inspectée/Inspected Site | O2: =Resultats!B5 -> Zone SET MFG
N3: Date(s) d'Inspection/Inspection Date(s) | O3: =Resultats!B11 -> 45967
B5: Q-Nr | C5: Question (FR) | D5: Question (EN) | E5: Categorie | F5: Reponse | G5: Resultat | H5: Resultat Pondere | I5: Resultat Max | J5: Resultat Max Pondere | N5: Commentaires/Comments | P5: Assessor Guidance | R5: QUEST Action Item
B6: 43 | C6: Le sol de la zone inspectée est propre et n'est pas souillé par des déversements (produits chimiques, incluant les huiles) ? | D6: The floor in the inspected area is clean and not contaminated with spills (chemicals, included oil)? | E6: 1 | F6: Oui | G6: =IF(F6="Oui",1,IF(F6="Partiellement",0.5,0)) -> 1 | H6: =G6*IF(E6=1, 0.7, 0.3) -> 0.7 | I6: =IF(F6="N/A", 0,1) -> 1 | J6: =I6*IF(E6=1, 0.7, 0.3) -> 0.7 | R6: Responsable de zone (Support : Marc Oszwald)
B7: 44 | C7: Un kit en cas de déversements est disponible, à proximité du lieu de stockage (armoire) et/ou d'utilisation des produits chimiques ? | D7: Is a spill kit available close to chemicals storage (cabinet) and/or use of chemicals area ? | E7: 1 | F7: N/A | G7: =IF(F7="Oui",1,IF(F7="Partiellement",0.5,0)) -> 0 | H7: =G7*IF(E7=1, 0.7, 0.3) -> 0 | I7: =IF(F7="N/A", 0,1) -> 0 | J7: =I7*IF(E7=1, 0.7, 0.3) -> 0 | N7: Pas de Splill Kit disponible dans la zone | R7: Responsable de zone (Support : Marc Oszwald)
B8: 45 | C8: Le kit est placé de telle manière à être visible et accessible facilement ? | D8: The spill Kit is placed in such a manner that it is easily visible and accessible ? | E8: 2 | F8: N/A | G8: =IF(F8="Oui",1,IF(F8="Partiellement",0.5,0)) -> 0 | H8: =G8*IF(E8=1, 0.7, 0.3) -> 0 | I8: =IF(F8="N/A", 0,1) -> 0 | J8: =I8*IF(E8=1, 0.7, 0.3) -> 0 | P8: Y a-t-il une signalétique spécifique permettant d'identifer rapidement le lieu de stockage du Spill Kit | R8: Responsable de zone (Support : Marc Oszwald)
B9: 46 | C9: Sur le kit est indiqué la description et l'inventaire du contenu (éléments absorbants qui le compose) ? | D9: On the Spill Kit is indicated the description and an inventory of its contents (the absorbants elements which compose it) ? | E9: 2 | F9: N/A | G9: =IF(F9="Oui",1,IF(F9="Partiellement",0.5,0)) -> 0 | H9: =G9*IF(E9=1, 0.7, 0.3) -> 0 | I9: =IF(F9="N/A", 0,1) -> 0 | J9: =I9*IF(E9=1, 0.7, 0.3) -> 0 | P9: Une etiquette collée sur le spill kit indique et decrit le type de spill kit et son contenu avec la quantité d'elements absorbants (boudins, coussins, feuilles d'absorbants …) | R9: Responsable de zone (Support : Marc Oszwald)
B10: 47 | C10: Le kit est-il complet (faire un rapide inventaire ) ? | D10: Is the spill kit complete with necessary PPE for minimum 2 persons (make a quick inventory) ? | E10: 1 | F10: N/A | G10: =IF(F10="Oui",1,IF(F10="Partiellement",0.5,0)) -> 0 | H10: =G10*IF(E10=1, 0.7, 0.3) -> 0 | I10: =IF(F10="N/A", 0,1) -> 0 | J10: =I10*IF(E10=1, 0.7, 0.3) -> 0 | P10: Les EPI obligatoires doivent etre : gants et lunettes de protection. Et selon les risques chimiques : masque, protection pour le corps et protection respiratoire. | R10: Responsable de zone (Support : Marc Oszwald)
B11: 48 | C11: La zone de stockage des produits chimiques est-elle équipée en bacs de rétention (capables de retenir au minimum 110% du plus gros container ou bien 50% du volume total des containers) ? | D11: Is the chemical storage area equiped with secondary containment (capable of holding at least 110% of the volume of the largest container or 50% of the total volume of containers)? | E11: 2 | F11: Oui | G11: =IF(F11="Oui",1,IF(F11="Partiellement",0.5,0)) -> 1 | H11: =G11*IF(E11=1, 0.7, 0.3) -> 0.3 | I11: =IF(F11="N/A", 0,1) -> 1 | J11: =I11*IF(E11=1, 0.7, 0.3) -> 0.3 | R11: Responsable de zone (Support : Marc Oszwald)
B12: 49 | C12: Les bacs de rétention sont-ils en bon état ? (Faire une rapide inspection visuelle des bacs : pas de corrosion, pas d'entailles, pas de fuites…) | D12: Are the secondary containment in good condition? (Make a quick visual inspection : no corrosion/rust, no notches, no leaks…) | E12: 1 | F12: Oui | G12: =IF(F12="Oui",1,IF(F12="Partiellement",0.5,0)) -> 1 | H12: =G12*IF(E12=1, 0.7, 0.3) -> 0.7 | I12: =IF(F12="N/A", 0,1) -> 1 | J12: =I12*IF(E12=1, 0.7, 0.3) -> 0.7 | R12: Responsable de zone (Support : Marc Oszwald)
B13: 50 | C13: La zone de stockage des déchets de produits chimiques est-elle définie et identifiée "zone d'elimination" ? | D13: Is the storage area for chemical waste products defined and identified "area d'elimination" ? | E13: 2 | F13: Oui | G13: =IF(F13="Oui",1,IF(F13="Partiellement",0.5,0)) -> 1 | H13: =G13*IF(E13=1, 0.7, 0.3) -> 0.3 | I13: =IF(F13="N/A", 0,1) -> 1 | J13: =I13*IF(E13=1, 0.7, 0.3) -> 0.3 | P13: Une zone doit etre clairement definie pour y deposer/stocker les dechets chimiques en attente d'élimination. | R13: Responsable de zone (Support : Marc Oszwald)
B14: 51 | C14: Les poubelles rouges destinées aux matériels souillés par des produits chimiques (tissus absorbants, chiffons, gants) sont-elles disponibles, et vidées ? | D14: Are the red trash bins for materials contaminated with chemicals (absorbants, rags, gloves) are available ? | E14: 2 | F14: Oui | G14: =IF(F14="Oui",1,IF(F14="Partiellement",0.5,0)) -> 1 | H14: =G14*IF(E14=1, 0.7, 0.3) -> 0.3 | I14: =IF(F14="N/A", 0,1) -> 1 | J14: =I14*IF(E14=1, 0.7, 0.3) -> 0.3 | R14: Responsable de zone (Support : Marc Oszwald)
H16: =SUM(H6:H14) -> 2.3
J17: =SUM(J6:J14) -> 2.3
K19: Pourcentage | M19: {=SUM(H6:H14)/SUM(J6:J14*(F6:F14<>"N/A")*(F6:F14<>""))} -> 1

Sheet IP
C2: Prevention des Blessures/Injury Prevention | F2: =IFERROR(M25,"") -> 0.91463415 | N2: Zone Inspectée/Inspected Site | O2: =Resultats!B5 -> Zone SET MFG
N3: Date(s) d'Inspection/Inspection Date(s) | O3: =Resultats!B11 -> 45967
B5: Q-Nr | C5: Question (FR) | D5: Question (EN) | E5: Categorie | F5: Reponse | G5: Resultat | H5: Resultat Pondere | I5: Resultat Max | J5: Resultat Max Pondere | N5: Commentaires/Comments | P5: Assessor Guidance | R5: QUEST Action Item
B6: 52 | C6: La zone inspectée est-elle dépourvue de risque pouvant entraîner une chute directe ou en glissant ou trébuchant ? | D6: Is the area free of risks that could lead to falling, slipping or tripping? | E6: 1 | F6: Oui | G6: =IF(F6="Oui",1,IF(F6="Partiellement",0.5,0)) -> 1 | H6: =G6*IF(E6=1, 0.7, 0.3) -> 0.7 | I6: =IF(F6="N/A", 0,1) -> 1 | J6: =I6*IF(E6=1, 0.7, 0.3) -> 0.7 | R6: Responsable de zone
B7: 53 | C7: Est-ce que les bagues sont enlevées dans la zone de travail (sauf bureaux)? | D7: Are finger rings removed in the inspected area (except offices)? | E7: 2 | F7: Oui | G7: =IF(F7="Oui",1,IF(F7="Partiellement",0.5,0)) -> 1 | H7: =G7*IF(E7=1, 0.7, 0.3) -> 0.3 | I7: =IF(F7="N/A", 0,1) -> 1 | J7: =I7*IF(E7=1, 0.7, 0.3) -> 0.3 | R7: Rappel de la règle
B8: 54 | C8: Les vêtements amples, porte badge, bracelets, chaines qui pendent, cravates, cheveux longs etc.... sont enlevés à proximité ou lors de l' utilisation d' un équipement en rotation? | D8: Are loose clothing, traditional headgear, dangling bracelets or chains, neckties, etc (this includes securing long hair) removed while working around machinery or moving parts? | E8: 2 | F8: Oui | G8: =IF(F8="Oui",1,IF(F8="Partiellement",0.5,0)) -> 1 | H8: =G8*IF(E8=1, 0.7, 0.3) -> 0.3 | I8: =IF(F8="N/A", 0,1) -> 1 | J8: =I8*IF(E8=1, 0.7, 0.3) -> 0.3 | P8: Tous objets ou accessoires pendants ou amples avec risque d'entrainement sont interdits à proximité des équipements de rotation Loose fitting traditional forms of headgear such as head scarfs are not permitted under any circumstances when working around rotating machinery. | R8: Rappel de la règle
B9: 55 | C9: Les zone de travail sont-elles propres et bien rangées ? Y a-t-il la place nécessaire pour travailler de manière ergonomique? | D9: Are the workbenches clean and well organized to allow ergonomic work conditions? | E9: 2 | F9: Oui | G9: =IF(F9="Oui",1,IF(F9="Partiellement",0.5,0)) -> 1 | H9: =G9*IF(E9=1, 0.7, 0.3) -> 0.3 | I9: =IF(F9="N/A", 0,1) -> 1 | J9: =I9*IF(E9=1, 0.7, 0.3) -> 0.3 | P9: Travail fréquent en zone verte. Bonne assise, maintien du dos droit | R9: 5S par responsable de zone.
B10: 56 | C10: Les zones de stockage sont-elles dépourvues de déchets ou d'équipements abandonnés ou empilés sur plusieurs couches pour un même niveau de stockage? | D10: Is the storage area free of trash, abandonned equipments or piled equipmenets for a same storage level? | E10: 2 | F10: Oui | G10: =IF(F10="Oui",1,IF(F10="Partiellement",0.5,0)) -> 1 | H10: =G10*IF(E10=1, 0.7, 0.3) -> 0.3 | I10: =IF(F10="N/A", 0,1) -> 1 | J10: =I10*IF(E10=1, 0.7, 0.3) -> 0.3 | R10: 5S par responsable de zone.
B11: 57 | C11: Les meules, les scies et les outils similaires sont pourvus des protections réglementaires requises ? | D11: Are grinders, saws and similar tools equiped with the required and regulatory protective devices? | E11: 1 | F11: N/A | G11: =IF(F11="Oui",1,IF(F11="Partiellement",0.5,0)) -> 0 | H11: =G11*IF(E11=1, 0.7, 0.3) -> 0 | I11: =IF(F11="N/A", 0,1) -> 0 | J11: =I11*IF(E11=1, 0.7, 0.3) -> 0 | P11: bouton d' arret d' urgence accessible pour tout equipement rotatif | R11: Responsable de zone (Support : Marc Oszwald)
B12: 58 | C12: Les ateliers ou bureaux sont - ils dépourvus de cartons, emballages, équipements ? La circulation est-elle aisee? | D12: Are the offices or workshops free of wastes? Is it easy to circulate? | E12: 2 | F12: Oui | G12: =IF(F12="Oui",1,IF(F12="Partiellement",0.5,0)) -> 1 | H12: =G12*IF(E12=1, 0.7, 0.3) -> 0.3 | I12: =IF(F12="N/A", 0,1) -> 1 | J12: =I12*IF(E12=1, 0.7, 0.3) -> 0.3 | R12: 5S par responsable de zone.
B13: 59 | C13: L'éclairage dans la zone est-il suffisant pour travailler convenablement ? | D13: Is the lighting in the area sufficient to work confortably? | E13: 2 | F13: Oui | G13: =IF(F13="Oui",1,IF(F13="Partiellement",0.5,0)) -> 1 | H13: =G13*IF(E13=1, 0.7, 0.3) -> 0.3 | I13: =IF(F13="N/A", 0,1) -> 1 | J13: =I13*IF(E13=1, 0.7, 0.3) -> 0.3 | R13: Responsable de zone (Support : Laurent Jolly)
B14: 60 | C14: Le chauffage et/ou la climatisation de la zone sont-ils suffisants ? Fonctionnent-ils convenablement ? | D14: Is the heating and/or ventilation and /or air conditioning sufficient for te inspected area? and do they work properly? | E14: 2 | F14: N/A | G14: =IF(F14="Oui",1,IF(F14="Partiellement",0.5,0)) -> 0 | H14: =G14*IF(E14=1, 0.7, 0.3) -> 0 | I14: =IF(F14="N/A", 0,1) -> 0 | J14: =I14*IF(E14=1, 0.7, 0.3) -> 0 | R14: Responsable de zone (Support : Laurent Jolly)
B15: 61 | C15: Les cordons "porte-badge" portés par le personnel s'ouvrent facilement en cas de tension excessive? | D15: Are the badge necklaces worn by employees the quick release type? | E15: 2 | F15: N/A | G15: =IF(F15="Oui",1,IF(F15="Partiellement",0.5,0)) -> 0 | H15: =G15*IF(E15=1, 0.7, 0.3) -> 0 | I15: =IF(F15="N/A", 0,1) -> 0 | J15: =I15*IF(E15=1, 0.7, 0.3) -> 0
B16: 62 | C16: Y a-t-il des posters rappelant l'usage des Techniques SIPP? | D16: Are there awarness poster to remind SIPP Techniques? | E16: 2 | F16: Oui | R16: MOP Ticket "reprographie" (Support : Marc Oszwald)
B17: 63 | C17: Les "pistolets" générateurs d'air chaud et fers à souder sont ils fixés sur un support de rangement adaptés, éteints si non utilisés? | D17: Are the heat gun and soldering iron properly stored in a dedicated holster fix to the bench? | E17: 2 | F17: Oui | G17: =IF(F17="Oui",1,IF(F17="Partiellement",0.5,0)) -> 1 | H17: =G17*IF(E17=1, 0.7, 0.3) -> 0.3 | I17: =IF(F17="N/A", 0,1) -> 1 | J17: =I17*IF(E17=1, 0.7, 0.3) -> 0.3 | R17: Responsable de zone (Support : Marc Oszwald)
B18: 64 | C18: Des étagères sont disponibles pour le stockage des pièces et des équipements, et les objets lourds sont stockés en partie basse ? | D18: Are shelves available for storing tools and equipment, and are heavy objects stored on the lower shelves? | E18: 2 | F18: Oui | G18: =IF(F18="Oui",1,IF(F18="Partiellement",0.5,0)) -> 1 | H18: =G18*IF(E18=1, 0.7, 0.3) -> 0.3 | I18: =IF(F18="N/A", 0,1) -> 1 | J18: =I18*IF(E18=1, 0.7, 0.3) -> 0.3 | P18: Manutention ou de levage manuel : charges lourdes stockées à hauteur d'homme, charges intermédiaires en bas, charges légères en haut Levage mécanique : charges lourdes stockées en bas, charges intermédiares au milieu, charges légères en haut | R18: Responsable de zone
B19: 65 | C19: Y a-t-il un téléphone facilement accessible et clairement identifié? Veuillez les tester en appelant le 3500. | D19: Is there a fix phone easily accessible and properly identified? | E19: 1 | F19: Partiellement | G19: =IF(F19="Oui",1,IF(F19="Partiellement",0.5,0)) -> 0.5 | H19: =G19*IF(E19=1, 0.7, 0.3) -> 0.35 | I19: =IF(F19="N/A", 0,1) -> 1 | J19: =I19*IF(E19=1, 0.7, 0.3) -> 0.7 | N19: présent mais pas connecté au réseau | R19: Responsable de zone (Support : Marc Oszwald)
B20: 66 | C20: Les plafonds et sous-plafonds sont-ils en bon état? | D20: Are sub ceilings free of falling hazard? | E20: 2 | F20: Oui | G20: =IF(F20="Oui",1,IF(F20="Partiellement",0.5,0)) -> 1 | H20: =G20*IF(E20=1, 0.7, 0.3) -> 0.3 | I20: =IF(F20="N/A", 0,1) -> 1 | J20: =I20*IF(E20=1, 0.7, 0.3) -> 0.3 | P20: risque de chute de dalle du faux plafond | R20: MOP Ticket "reprographie" (Support : Marc Oszwald)
H22: =SUM(H6:H19) -> 3.45
J23: =SUM(J6:J19) -> 3.8
K25: Pourcentage | M25: {=SUM(H6:H20)/SUM(J6:J20*(F6:F20<>"N/A")*(F6:F20<>""))} -> 0.91463415

Sheet ML
C2: Levage Mécanique / Mechanical Lifting | F2: =IFERROR(M18,"") -> 0.953125 | N2: Zone Inspectée/Inspected Site | O2: =Resultats!B5 -> Zone SET MFG
N3: Date(s) d'Inspection/Inspection Date(s) | O3: =Resultats!B11 -> 45967
B5: Q-Nr | C5: Question (FR) | D5: Question (EN) | E5: Categorie | F5: Reponse | G5: Resultat | H5: Resultat Pondere | I5: Resultat Max | J5: Resultat Max Pondere | N5: Commentaires/Comments | P5: Assessor Guidance | R5: QUEST Action Item
B6: 67 | C6: Les élingues et autres accessoires de levage (chaînes, etc.) sont-ils inspectés au moins une fois cette année en accord avec la réglementation locale (Code du Travail) et les Standards Schlumberger ? | D6: Have the slings and lifting accessories been inspected annualy according to the local regulation and SLB Standards? | E6: 1 | F6: Oui | G6: =IF(F6="Oui",1,IF(F6="Partiellement",0.5,0)) -> 1 | H6: =G6*IF(E6=1, 0.7, 0.3) -> 0.7 | I6: =IF(F6="N/A", 0,1) -> 1 | J6: =I6*IF(E6=1, 0.7, 0.3) -> 0.7 | P6: Vérifier la présence d'un identifiant / Tag de l'année en cours pour les élingues ("Yes" si 100% des élingues) | R6: Responsable de zone + Responsable levage (Tag elingue : PPE Coordinator)
B7: 68 | C7: Les élingues et les accessoires de levage sont-ils en bon état et rangés de manière appropriée ? | D7: Are the sling in good condition and stored in a safe manner? | E7: 2 | F7: Oui | G7: =IF(F7="Oui",1,IF(F7="Partiellement",0.5,0)) -> 1 | H7: =G7*IF(E7=1, 0.7, 0.3) -> 0.3 | I7: =IF(F7="N/A", 0,1) -> 1 | J7: =I7*IF(E7=1, 0.7, 0.3) -> 0.3 | P7: Les élingues doivent être rangées sur des racks, les zones de stockage doivent être à l'abri de la lumière et de la pluie. | R7: Responsable de zone + Responsable levage
B8: 69 | C8: Les élingues et les accessoires (chaînes, etc.) ont été étiquetées et repérées ? Un registre ou inventaire est il disponible? | D8: Have the slings been tagged and registered? Is there a recent inventory a gear register available? | E8: 2 | F8: Oui | G8: =IF(F8="Oui",1,IF(F8="Partiellement",0.5,0)) -> 1 | H8: =G8*IF(E8=1, 0.7, 0.3) -> 0.3 | I8: =IF(F8="N/A", 0,1) -> 1 | J8: =I8*IF(E8=1, 0.7, 0.3) -> 0.3 | P8: Les élingues et accessoires de levage doivent être identifiables grâce à un numéro de série. | R8: Responsable de zone + Responsable levage
B9: 70 | C9: La capacité en charge des racks de stockage est-elle clairement indiquée ? | D9: Is the load capacity for storage racks clearly indicated? | E9: 2 | F9: Oui | G9: =IF(F9="Oui",1,IF(F9="Partiellement",0.5,0)) -> 1 | H9: =G9*IF(E9=1, 0.7, 0.3) -> 0.3 | I9: =IF(F9="N/A", 0,1) -> 1 | J9: =I9*IF(E9=1, 0.7, 0.3) -> 0.3 | P9: Une plaque indiquant la charge maximale par niveau doit être fixée sur la baie. | R9: Responsable de zone + Responsable levage
B10: 71 | C10: La charge maximale d'utilisation est clairement indiquée sur les équipments de levage? | D10: Is the max safe working load clearly indicated on lifting equipment? | E10: 2 | F10: Oui | G10: =IF(F10="Oui",1,IF(F10="Partiellement",0.5,0)) -> 1 | H10: =G10*IF(E10=1, 0.7, 0.3) -> 0.3 | I10: =IF(F10="N/A", 0,1) -> 1 | J10: =I10*IF(E10=1, 0.7, 0.3) -> 0.3 | R10: Responsable de zone + Responsable levage
B11: 72 | C11: Les équipements de levage sont -ils visuellement en bon état et fonctionnent-ils correctement? | D11: Is the lifting equipment in good condition and working properly? | E11: 2 | F11: Oui | G11: =IF(F11="Oui",1,IF(F11="Partiellement",0.5,0)) -> 1 | H11: =G11*IF(E11=1, 0.7, 0.3) -> 0.3 | I11: =IF(F11="N/A", 0,1) -> 1 | J11: =I11*IF(E11=1, 0.7, 0.3) -> 0.3 | P11: Vérifier si l'équipement est en utilisation ou dans la check list journalière. Si problème ou dysfonctionnement identifié dans la checklist, une action est elle en cours? | R11: Responsable de zone + Responsable levage
B12: 73 | C12: Les équipements de levage sont-ils inspectés périodiquement suivant les normes européennes et les standards Schlumberger? | D12: Is the lifting equipment inspected following the local regulation and SLB Standards? Is APAVE tag visible and up to date? | E12: 1 | F12: Oui | G12: =IF(F12="Oui",1,IF(F12="Partiellement",0.5,0)) -> 1 | H12: =G12*IF(E12=1, 0.7, 0.3) -> 0.7 | I12: =IF(F12="N/A", 0,1) -> 1 | J12: =I12*IF(E12=1, 0.7, 0.3) -> 0.7 | P12: Vérifier la présence du sticker de l'APAVE ou autre certification. | R12: Responsable de zone + Responsable levage
B13: 74 | C13: Le check-list d'inspection hebdomadaire avant utilisation est-elle remplie et signée pour les équipements de levage (pont roulant, palan, chariot élévateur)? | D13: Has the weekly Inspection Log been completed and signed to prove that the locally designed daily (or immediately prior to use) visual inspections for mechanical lifting devices (overhead, fixed and mobile cranes, forklifts, etc) are being conducted? | E13: 2 | F13: Partiellement | G13: =IF(F13="Oui",1,IF(F13="Partiellement",0.5,0)) -> 0.5 | H13: =G13*IF(E13=1, 0.7, 0.3) -> 0.15 | I13: =IF(F13="N/A", 0,1) -> 1 | J13: =I13*IF(E13=1, 0.7, 0.3) -> 0.3 | N13: Pas de Check -List ou QR Code | P13: Vérifier 2 ou 3 équipements de levage dans la zone et si les checklists sont remplies régulièrement en fonction de la fréquence d'utilisation. Lisible et avec le nom | R13: Responsable de zone + Responsable levage
H15: =SUM(H6:H13) -> 3.05
J16: =SUM(J6:J13) -> 3.2
K18: Pourcentage | M18: {=SUM(H6:H13)/SUM(J6:J13*(F6:F13<>"N/A")*(F6:F13<>""))} -> 0.953125

Sheet SEC
C2: Sureté / Security | F2: 1 | N2: Zone Inspectée/Inspected Site | O2: =Resultats!B5 -> Zone SET MFG
N3: Date(s) d'Inspection/Inspection Date(s) | O3: =Resultats!B11 -> 45967
B5: Q-Nr | C5: Question (FR) | D5: Question (EN) | E5: Categorie | F5: Reponse | G5: Resultat | H5: Resultat Pondere | I5: Resultat Max | J5: Resultat Max Pondere | N5: Commentaires/Comments | P5: Assessor Guidance | R5: QUEST Action Item
B6: 75 | C6: La zone est elle fermée et contrôlée par lecteur de badge ? | D6: The area is closed and controlled by card reader ? | E6: 2 | F6: N/A | G6: =IF(F6="Oui",1,IF(F6="Partiellement",0.5,0)) -> 0 | H6: =G6*IF(E6=1, 0.7, 0.3) -> 0 | I6: =IF(F6="N/A", 0,1) -> 0 | J6: =I6*IF(E6=1, 0.7, 0.3) -> 0 | P6: Concerne uniquement les zones sécurisées : nucléaire, laboratoires produits chimiques dangeureux (poison, Très Toxique et toxicité aigue Cat 1), stockage… | R6: Tickets Services techniques
B7: 76 | C7: Les portes d'accès donnant sur l'extérieur du bâtiment sont équipées d'un contrôle d'accès ? | D7: The access doors allowing external access to the building are fitted with an access control ? | E7: 1 | F7: Oui | G7: =IF(F7="Oui",1,IF(F7="Partiellement",0.5,0)) -> 1 | H7: =G7*IF(E7=1, 0.7, 0.3) -> 0.7 | I7: =IF(F7="N/A", 0,1) -> 1 | J7: =I7*IF(E7=1, 0.7, 0.3) -> 0.7 | P7: Concerne la porte d'accès extérieure la plus proche de la zone inspectée, à identifier | R7: Tickets Services techniques
B8: 77 | C8: Les lecteurs de badge fonctionnent-ils correctement ? | D8: Are Card Readers working properly ? | E8: 2 | F8: Oui | G8: =IF(F8="Oui",1,IF(F8="Partiellement",0.5,0)) -> 1 | H8: =G8*IF(E8=1, 0.7, 0.3) -> 0.3 | I8: =IF(F8="N/A", 0,1) -> 1 | J8: =I8*IF(E8=1, 0.7, 0.3) -> 0.3 | P8: Identifier le lecteur par son numéro en cas de dysfonctionnement, champ "Remarks" et faire un MOP | R8: Tickets Services techniques
B9: 78 | C9: Les visiteurs et/ou sous-traitants présents dans la zone portent leur badge de façon visible ? | D9: Visitors and/or Contractors presents in the area are wearing their badge in a visible way ? | E9: 2 | F9: N/A | G9: =IF(F9="Oui",1,IF(F9="Partiellement",0.5,0)) -> 0 | H9: =G9*IF(E9=1, 0.7, 0.3) -> 0 | I9: =IF(F9="N/A", 0,1) -> 0 | J9: =I9*IF(E9=1, 0.7, 0.3) -> 0 | R9: Rappel de la règle
B10: 79 | C10: Les visiteurs sont accompagnés par leur hôte ? | D10: Visitors are accompanied by their host ? | E10: 1 | F10: N/A | G10: =IF(#REF!="Oui",1,IF(#REF!="Partiellement",0.5,0)) -> #REF! | H10: =G10*IF(E10=1, 0.7, 0.3) -> #REF! | I10: =IF(#REF!="N/A", 0,1) -> #REF! | J10: 0.7 | R10: Rappel de la règle
B11: 80 | C11: Les ordinateurs portable (Bureau et Atelier) sont sécurisés au moyen d'un cable attaché à une partie fixe ? | D11: Computers laptop (Office and Workshop) are secured by means of a cable attached to a fixed part ? | E11: 2 | F11: Oui | G11: =IF(#REF!="Oui",1,IF(#REF!="Partiellement",0.5,0)) -> #REF! | H11: =G11*IF(E11=1, 0.7, 0.3) -> #REF! | I11: =IF(#REF!="N/A", 0,1) -> #REF! | J11: 0.7 | P11: P = Partiel : préciser le nombre de PC trouvés non attachés | R11: Rappel de la règle
B12: 81 | C12: Les écrans des ordinateurs de bureau inutilisés sont protégés par mot de passe ? | D12: The screens of unattended office computers are protected by password ? | E12: 2 | F12: Oui | G12: =IF(#REF!="Oui",1,IF(#REF!="Partiellement",0.5,0)) -> #REF! | H12: =G12*IF(E12=1, 0.7, 0.3) -> #REF! | I12: =IF(#REF!="N/A", 0,1) -> #REF! | J12: 0.7 | R12: Rappel de la règle
B13: 82 | C13: Le symbole "PC Security Check" des ordinateurs en utilisation est vert ? | D13: The " PC Security Check " symbol of computers in use are green ? | E13: 2 | F13: N/A | G13: =IF(F13="Oui",1,IF(F13="Partiellement",0.5,0)) -> 0 | H13: =G13*IF(E13=1, 0.7, 0.3) -> 0 | I13: =IF(F13="N/A", 0,1) -> 0 | J13: =I13*IF(E13=1, 0.7, 0.3) -> 0 | R13: Rappel de la règle
B14: 83 | C14: Il n'y a pas de document confidentiel dans les poubelles (papiers, CD, DVD…) ? | D14: There are not confidential documents in trash bins (papers, CD, DVD) ? | E14: 1 | F14: N/A | G14: =IF(F14="Oui",1,IF(F14="Partiellement",0.5,0)) -> 0 | H14: =G14*IF(E14=1, 0.7, 0.3) -> 0 | I14: =IF(F14="N/A", 0,1) -> 0 | J14: =I14*IF(E14=1, 0.7, 0.3) -> 0 | R14: Rappel de la règle
H16: =SUM(H6:H14) -> #REF!
J17: =SUM(J6:J14) -> 3.1
K19: Pourcentage | M19: {=SUM(H6:H14)/SUM(J6:J14*(F6:F14<>"N/A")*(F6:F14<>""))} -> #REF!

Sheet RWP
B1: Template for import of remedial actions in QUEST | K1: H
A2: Action Item Summary | B2: Comments | C2: Priority | D2: Responsibility | E2: Target Date | F2: Close Date | K2: M
A3: (limited to 50 characters) | B3: (limited to 255 characters) | C3: (H, M or L) | D3: (GIN Number Or LDAP Alias) | E3: (Date) | F3: (Date) | K3: L
A4: Follow up on Audit RWP closure. | B4: Audit Team Leader to follow up on RWP closure to ensure actions are properly closed out in a timely manner to comply with Segment/Function and SLB Standards and evaluate the implementation of the SLB Management System | C4: =INDIRECT("k"&K4) -> H | D4: Enter 8 digits GIN Number or LDAP Alias of the leader | K4: 1
C5: =INDIRECT("k"&K5) -> M | K5: 2
C6: =INDIRECT("k"&K6) -> M | K6: 2
C7: =INDIRECT("k"&K7) -> M | K7: 2
C8: =INDIRECT("k"&K8) -> M | K8: 2
C9: =INDIRECT("k"&K9) -> M | K9: 2
C10: =INDIRECT("k"&K10) -> M | K10: 2
C11: =INDIRECT("k"&K11) -> M | K11: 2
C12: =INDIRECT("k"&K12) -> M | K12: 2
C13: =INDIRECT("k"&K13) -> M | K13: 2
C14: =INDIRECT("k"&K14) -> M | K14: 2
C15: =INDIRECT("k"&K15) -> M | K15: 2
C16: =INDIRECT("k"&K16) -> M | K16: 2
... C53: =INDIRECT("k"&K53) -> M | K53: 2

Sheet Action Item Tab
